=== Scaffold Execution Log ===
Model: openai/o3
Timestamp: 20250715_181613

=== INPUT ===
- - - - - - - . - - - - - - -
- - - - - - - . - - - - - - -
- - - - - - - . - - - - - - -
- - - - - - . . . . - - - - -
- - - - - - - . - - - . - - -
- - - - . - - - - - - - - - .
- - - . - - - - - - - - - . .
. . . - - - - - - - - - . . .
. . - - - - - - - - - . - - -
. - - - - - - - - - . - - - -
- - - . - - - . - - - - - - -
- - - - - . . . . - - - - - -
- - - - - - - . - - - - - - -
- - - - - - - . - - - - - - -
- - - - - - - . - - - - - - -

Across:
  1. "Braveheart" villain
  8. Shoddy treatment
 15. Monodon monoceros, more familiarly
 16. Qatar, e.g.
 17. "Eh? Eh?"
 18. Defense secretary under Obama
 19. Día después de hoy
 20. Utah home of Weber State University
 21. Shell game?
 23. ___ es Salaam
 25. Ending with love or tap
 26. Bottom of the barrel
 27. Marion ___, Best Actress winner for "La Vie en Rose"
 30. 20th-century map inits.
 31. First person to fly solo around the world (1933)
 32. Gesture signifying perfection
 33. Part of a plan?
 34. Tip of a writing implement
 37. Circuit building block
 38. Cash crop of South America
 39. Use curlers on, say
 40. Match
 41. Like many a chute in Chutes and Ladders
 43. Poorly suited
 45. Some grilled meat dishes
 46. Ground
 49. ___ Command (classic arcade game)
 50. Small plane for short flights
 51. Entourage
 52. Things sometimes lost in sofa cushions
 53. Brought (out)

Down:
  1. Smooth veneers
  2. Award in a lawsuit
  3. Metaphor for a difficult ordeal
  4. "Oh, darn!"
  5. Animal whose name means, literally, "nose"
  6. Field of informatics
  7. ___ du Diable (notorious French penal colony)
  8. Status, informally
  9. Org. with a snake in its logo
 10. No matter what
 11. Remnant
 12. Suffer abject humiliation
 13. Opposite of cut
 14. Has a list
 22. Method of music education
 23. Aids in making craft projects, in brief
 24. Super-G competitor
 28. A.C. : ___ :: D.C. : Edison
 29. Doofus
 31. Question asked when going through an old family photo album, perhaps
 32. Abbr. on a receipt
 33. Joint venture?
 34. What a circular argument has
 35. Color of a glacier
 36. Person who's corrupt by nature
 37. Detective ___ Briscoe of "Law & Order"
 38. Pays a fare to get there, say
 39. Atkins diet no-no
 42. Must
 44. Relationship phrase
 47. Program file suffix
 48. Lead-in to course
 49. 1980s TV celeb with a role in "Rocky III"

=== STDERR ===
2025-07-16 01:40:50,676 [ERROR] Error occurred: Request timed out.
Traceback (most recent call last):
  File "/usr/local/lib/python3.10/site-packages/httpx/_transports/default.py", line 101, in map_httpcore_exceptions
    yield
  File "/usr/local/lib/python3.10/site-packages/httpx/_transports/default.py", line 250, in handle_request
    resp = self._pool.handle_request(req)
  File "/usr/local/lib/python3.10/site-packages/httpcore/_sync/connection_pool.py", line 256, in handle_request
    raise exc from None
  File "/usr/local/lib/python3.10/site-packages/httpcore/_sync/connection_pool.py", line 236, in handle_request
    response = connection.handle_request(
  File "/usr/local/lib/python3.10/site-packages/httpcore/_sync/connection.py", line 103, in handle_request
    return self._connection.handle_request(request)
  File "/usr/local/lib/python3.10/site-packages/httpcore/_sync/http11.py", line 136, in handle_request
    raise exc
  File "/usr/local/lib/python3.10/site-packages/httpcore/_sync/http11.py", line 106, in handle_request
    ) = self._receive_response_headers(**kwargs)
  File "/usr/local/lib/python3.10/site-packages/httpcore/_sync/http11.py", line 177, in _receive_response_headers
    event = self._receive_event(timeout=timeout)
  File "/usr/local/lib/python3.10/site-packages/httpcore/_sync/http11.py", line 217, in _receive_event
    data = self._network_stream.read(
  File "/usr/local/lib/python3.10/site-packages/httpcore/_backends/sync.py", line 126, in read
    with map_exceptions(exc_map):
  File "/usr/local/lib/python3.10/contextlib.py", line 153, in __exit__
    self.gen.throw(typ, value, traceback)
  File "/usr/local/lib/python3.10/site-packages/httpcore/_exceptions.py", line 14, in map_exceptions
    raise to_exc(exc) from exc
httpcore.ReadTimeout: The read operation timed out

The above exception was the direct cause of the following exception:

Traceback (most recent call last):
  File "/usr/local/lib/python3.10/site-packages/openai/_base_client.py", line 979, in request
    response = self._client.send(
  File "/usr/local/lib/python3.10/site-packages/httpx/_client.py", line 914, in send
    response = self._send_handling_auth(
  File "/usr/local/lib/python3.10/site-packages/httpx/_client.py", line 942, in _send_handling_auth
    response = self._send_handling_redirects(
  File "/usr/local/lib/python3.10/site-packages/httpx/_client.py", line 979, in _send_handling_redirects
    response = self._send_single_request(request)
  File "/usr/local/lib/python3.10/site-packages/httpx/_client.py", line 1014, in _send_single_request
    response = transport.handle_request(request)
  File "/usr/local/lib/python3.10/site-packages/httpx/_transports/default.py", line 249, in handle_request
    with map_httpcore_exceptions():
  File "/usr/local/lib/python3.10/contextlib.py", line 153, in __exit__
    self.gen.throw(typ, value, traceback)
  File "/usr/local/lib/python3.10/site-packages/httpx/_transports/default.py", line 118, in map_httpcore_exceptions
    raise mapped_exc(message) from exc
httpx.ReadTimeout: The read operation timed out

The above exception was the direct cause of the following exception:

Traceback (most recent call last):
  File "<string>", line 32, in <module>
  File "/workspace/scaffold/scaffold.py", line 6, in process_input
    return execute_llm(PROMPT + input_string)
  File "/app/llm_executor.py", line 39, in execute_llm
    result = executor_llm.generate_response(prompt, system_prompt)
  File "/app/src/scaffold_learning/core/llm_interfaces.py", line 69, in generate_response
    response = client.responses.create(
  File "/usr/local/lib/python3.10/site-packages/openai/resources/responses/responses.py", line 735, in create
    return self._post(
  File "/usr/local/lib/python3.10/site-packages/openai/_base_client.py", line 1256, in post
    return cast(ResponseT, self.request(cast_to, opts, stream=stream, stream_cls=stream_cls))
  File "/usr/local/lib/python3.10/site-packages/openai/_base_client.py", line 997, in request
    raise APITimeoutError(request=request) from err
openai.APITimeoutError: Request timed out.

=== ERROR ===
Error from scaffold (exit code 1):
2025-07-16 01:40:50,676 [ERROR] Error occurred: Request timed out.
Traceback (most recent call last):
  File "/usr/local/lib/python3.10/site-packages/httpx/_transports/default.py", line 101, in map_httpcore_exceptions
    yield
  File "/usr/local/lib/python3.10/site-packages/httpx/_transports/default.py", line 250, in handle_request
    resp = self._pool.handle_request(req)
  File "/usr/local/lib/python3.10/site-packages/httpcore/_sync/connection_pool.py", line 256, in handle_request
    raise exc from None
  File "/usr/local/lib/python3.10/site-packages/httpcore/_sync/connection_pool.py", line 236, in handle_request
    response = connection.handle_request(
  File "/usr/local/lib/python3.10/site-packages/httpcore/_sync/connection.py", line 103, in handle_request
    return self._connection.handle_request(request)
  File "/usr/local/lib/python3.10/site-packages/httpcore/_sync/http11.py", line 136, in handle_request
    raise exc
  File "/usr/local/lib/python3.10/site-packages/httpcore/_sync/http11.py", line 106, in handle_request
    ) = self._receive_response_headers(**kwargs)
  File "/usr/local/lib/python3.10/site-packages/httpcore/_sync/http11.py", line 177, in _receive_response_headers
    event = self._receive_event(timeout=timeout)
  File "/usr/local/lib/python3.10/site-packages/httpcore/_sync/http11.py", line 217, in _receive_event
    data = self._network_stream.read(
  File "/usr/local/lib/python3.10/site-packages/httpcore/_backends/sync.py", line 126, in read
    with map_exceptions(exc_map):
  File "/usr/local/lib/python3.10/contextlib.py", line 153, in __exit__
    self.gen.throw(typ, value, traceback)
  File "/usr/local/lib/python3.10/site-packages/httpcore/_exceptions.py", line 14, in map_exceptions
    raise to_exc(exc) from exc
httpcore.ReadTimeout: The read operation timed out

The above exception was the direct cause of the following exception:

Traceback (most recent call last):
  File "/usr/local/lib/python3.10/site-packages/openai/_base_client.py", line 979, in request
    response = self._client.send(
  File "/usr/local/lib/python3.10/site-packages/httpx/_client.py", line 914, in send
    response = self._send_handling_auth(
  File "/usr/local/lib/python3.10/site-packages/httpx/_client.py", line 942, in _send_handling_auth
    response = self._send_handling_redirects(
  File "/usr/local/lib/python3.10/site-packages/httpx/_client.py", line 979, in _send_handling_redirects
    response = self._send_single_request(request)
  File "/usr/local/lib/python3.10/site-packages/httpx/_client.py", line 1014, in _send_single_request
    response = transport.handle_request(request)
  File "/usr/local/lib/python3.10/site-packages/httpx/_transports/default.py", line 249, in handle_request
    with map_httpcore_exceptions():
  File "/usr/local/lib/python3.10/contextlib.py", line 153, in __exit__
    self.gen.throw(typ, value, traceback)
  File "/usr/local/lib/python3.10/site-packages/httpx/_transports/default.py", line 118, in map_httpcore_exceptions
    raise mapped_exc(message) from exc
httpx.ReadTimeout: The read operation timed out

The above exception was the direct cause of the following exception:

Traceback (most recent call last):
  File "<string>", line 32, in <module>
  File "/workspace/scaffold/scaffold.py", line 6, in process_input
    return execute_llm(PROMPT + input_string)
  File "/app/llm_executor.py", line 39, in execute_llm
    result = executor_llm.generate_response(prompt, system_prompt)
  File "/app/src/scaffold_learning/core/llm_interfaces.py", line 69, in generate_response
    response = client.responses.create(
  File "/usr/local/lib/python3.10/site-packages/openai/resources/responses/responses.py", line 735, in create
    return self._post(
  File "/usr/local/lib/python3.10/site-packages/openai/_base_client.py", line 1256, in post
    return cast(ResponseT, self.request(cast_to, opts, stream=stream, stream_cls=stream_cls))
  File "/usr/local/lib/python3.10/site-packages/openai/_base_client.py", line 997, in request
    raise APITimeoutError(request=request) from err
openai.APITimeoutError: Request timed out.

